Workbook

Sheet Cover
B2: Job Cost & WIP Report
B3: Boreal Ridge Construction Ltd. (fictional company)
B4: Period ending September 30, 2026
B6: SAMPLE DATA NOTICE | C6: Representative rebuild of ERP cost reporting delivered for construction clients. The company, jobs, vendors and all figures are synthetic; client data is confidential.
B8: Report date | C8: =DATE(2026,9,30) -> 46295
B10: SHEETS
B11: WIP Schedule | C11: Portfolio view: contract, cost to date, forecast cost, % complete, earned revenue, over/(under) billing, projected margin and fade, CPI and backlog for every job.
B12: Job Detail | C12: Pick a job number in the yellow cell to see its cost-code report, forecast overruns and labour productivity.
B13: Cost Report | C13: Cost-code level calculation that feeds both reports (one row per job / cost code budget line).
B14: Monthly Cost | C14: Monthly and cumulative cost by job from the job cost ledger, with a portfolio cost curve.
B15: Data_* tabs | C15: Raw ERP exports: job master, cost codes, budgets, PM progress, commitments, job cost detail, billings. Paste a new month's export over these tables to refresh.
B17: METHOD
B18: Earned value | C18: Revised budget x PM-reported physical % complete for the cost code.
B19: CPI | C19: Earned value / actual cost. Below 1.00 means the work is costing more than budgeted.
B20: Forecast cost (EAC) | C20: Subcontract & material lines with a commitment: the greater of committed value and cost to date. Other lines in progress: cost to date + remaining budget / CPI. Lines not started: revised budget.
B21: % complete (revenue) | C21: Cost-to-cost method: cost to date / forecast cost.
B22: Earned revenue | C22: Revised contract x % complete.
B23: Over/(under) billing | C23: Billed to date - earned revenue. Positive = billings in excess of revenue (liability); negative = revenue in excess of billings (asset).
B24: Margin fade | C24: Projected margin % - bid margin %. Negative = profit eroding since bid.
B26: COLOUR KEY
B27: Blue on yellow | C27: Input you can change (the job selector on Job Detail).
B28: Black | C28: Formula.

Sheet WIP Schedule
A1: Work-in-Progress Schedule
A2: Boreal Ridge Construction Ltd. (fictional) · Period ending September 30, 2026 · Percentage-of-completion, cost-to-cost method
A4: Job No | B4: Job Name | C4: PM | D4: Status | E4: Revised Contract | F4: Revised Budget | G4: Cost to Date | H4: Committed | I4: Forecast Cost (EAC) | J4: Cost to Complete | K4: % Complete | L4: Earned Revenue | M4: Billed to Date | N4: Over/(Under) Billing | O4: Projected Gross Profit | P4: Projected Margin | Q4: Bid Margin | R4: Margin Fade | S4: CPI | T4: Backlog
A5: 23-098 | B5: =INDEX(Data_Jobs!$B:$B,MATCH($A5,Data_Jobs!$A:$A,0)) -> Transit Bus Garage Upgrade | C5: =INDEX(Data_Jobs!$E:$E,MATCH($A5,Data_Jobs!$A:$A,0)) -> R. Singh | D5: =INDEX(Data_Jobs!$L:$L,MATCH($A5,Data_Jobs!$A:$A,0)) -> Substantially complete | E5: =INDEX(Data_Jobs!$K:$K,MATCH($A5,Data_Jobs!$A:$A,0)) -> 15462000 | F5: =SUMIFS('Cost Report'!$G$5:$G$180,'Cost Report'!$A$5:$A$180,$A5) -> 13811100 | G5: =SUMIFS('Cost Report'!$H$5:$H$180,'Cost Report'!$A$5:$A$180,$A5) -> 14275865 | H5: =SUMIFS('Cost Report'!$I$5:$I$180,'Cost Report'!$A$5:$A$180,$A5) -> 11358200 | I5: =SUMIFS('Cost Report'!$M$5:$M$180,'Cost Report'!$A$5:$A$180,$A5) -> 14408910 | J5: =I5-G5 -> 133044.48 | K5: =IF(I5>0,G5/I5,0) -> 0.99076651 | L5: =E5*K5 -> 15319232 | M5: =SUMIFS(Data_Billings!$E:$E,Data_Billings!$D:$D,$A5) -> 15319587 | N5: =M5-L5 -> 355.62911 | O5: =E5-I5 -> 1053090.1 | P5: =IF(E5>0,O5/E5,0) -> 0.068108274 | Q5: =INDEX(Data_Jobs!$H:$H,MATCH($A5,Data_Jobs!$A:$A,0)) -> 0.105 | R5: =P5-Q5 -> -0.036891726 | S5: =IF(G5>0,SUMIFS('Cost Report'!$K$5:$K$180,'Cost Report'!$A$5:$A$180,$A5)/G5,"") -> 0.96596512 | T5: =E5-L5 -> 142768.17
A6: 24-101 | B6: =INDEX(Data_Jobs!$B:$B,MATCH($A6,Data_Jobs!$A:$A,0)) -> Leduc Distribution Warehouse | C6: =INDEX(Data_Jobs!$E:$E,MATCH($A6,Data_Jobs!$A:$A,0)) -> M. Okafor | D6: =INDEX(Data_Jobs!$L:$L,MATCH($A6,Data_Jobs!$A:$A,0)) -> In progress | E6: =INDEX(Data_Jobs!$K:$K,MATCH($A6,Data_Jobs!$A:$A,0)) -> 22245000 | F6: =SUMIFS('Cost Report'!$G$5:$G$180,'Cost Report'!$A$5:$A$180,$A6) -> 20085200 | G6: =SUMIFS('Cost Report'!$H$5:$H$180,'Cost Report'!$A$5:$A$180,$A6) -> 19031041 | H6: =SUMIFS('Cost Report'!$I$5:$I$180,'Cost Report'!$A$5:$A$180,$A6) -> 15186100 | I6: =SUMIFS('Cost Report'!$M$5:$M$180,'Cost Report'!$A$5:$A$180,$A6) -> 19799870 | J6: =I6-G6 -> 768828.93 | K6: =IF(I6>0,G6/I6,0) -> 0.96117 | L6: =E6*K6 -> 21381227 | M6: =SUMIFS(Data_Billings!$E:$E,Data_Billings!$D:$D,$A6) -> 22246320 | N6: =M6-L6 -> 865093.75 | O6: =E6-I6 -> 2445129.6 | P6: =IF(E6>0,O6/E6,0) -> 0.10991817 | Q6: =INDEX(Data_Jobs!$H:$H,MATCH($A6,Data_Jobs!$A:$A,0)) -> 0.095 | R6: =P6-Q6 -> 0.014918166 | S6: =IF(G6>0,SUMIFS('Cost Report'!$K$5:$K$180,'Cost Report'!$A$5:$A$180,$A6)/G6,"") -> 1.0270026 | T6: =E6-L6 -> 863773.3
A7: 24-104 | B7: =INDEX(Data_Jobs!$B:$B,MATCH($A7,Data_Jobs!$A:$A,0)) -> School Modernization - Phase 2 | C7: =INDEX(Data_Jobs!$E:$E,MATCH($A7,Data_Jobs!$A:$A,0)) -> J. Tremblay | D7: =INDEX(Data_Jobs!$L:$L,MATCH($A7,Data_Jobs!$A:$A,0)) -> In progress | E7: =INDEX(Data_Jobs!$K:$K,MATCH($A7,Data_Jobs!$A:$A,0)) -> 16538000 | F7: =SUMIFS('Cost Report'!$G$5:$G$180,'Cost Report'!$A$5:$A$180,$A7) -> 14705200 | G7: =SUMIFS('Cost Report'!$H$5:$H$180,'Cost Report'!$A$5:$A$180,$A7) -> 13766951 | H7: =SUMIFS('Cost Report'!$I$5:$I$180,'Cost Report'!$A$5:$A$180,$A7) -> 11693400 | I7: =SUMIFS('Cost Report'!$M$5:$M$180,'Cost Report'!$A$5:$A$180,$A7) -> 15394483 | J7: =I7-G7 -> 1627531.9 | K7: =IF(I7>0,G7/I7,0) -> 0.89427824 | L7: =E7*K7 -> 14789573 | M7: =SUMIFS(Data_Billings!$E:$E,Data_Billings!$D:$D,$A7) -> 14186235 | N7: =M7-L7 -> -603338.01 | O7: =E7-I7 -> 1143516.7 | P7: =IF(E7>0,O7/E7,0) -> 0.069144798 | Q7: =INDEX(Data_Jobs!$H:$H,MATCH($A7,Data_Jobs!$A:$A,0)) -> 0.11 | R7: =P7-Q7 -> -0.040855202 | S7: =IF(G7>0,SUMIFS('Cost Report'!$K$5:$K$180,'Cost Report'!$A$5:$A$180,$A7)/G7,"") -> 0.9717383 | T7: =E7-L7 -> 1748426.5
A8: 24-107 | B8: =INDEX(Data_Jobs!$B:$B,MATCH($A8,Data_Jobs!$A:$A,0)) -> Fabrication Shop Expansion | C8: =INDEX(Data_Jobs!$E:$E,MATCH($A8,Data_Jobs!$A:$A,0)) -> M. Okafor | D8: =INDEX(Data_Jobs!$L:$L,MATCH($A8,Data_Jobs!$A:$A,0)) -> In progress | E8: =INDEX(Data_Jobs!$K:$K,MATCH($A8,Data_Jobs!$A:$A,0)) -> 10160000 | F8: =SUMIFS('Cost Report'!$G$5:$G$180,'Cost Report'!$A$5:$A$180,$A8) -> 8928400 | G8: =SUMIFS('Cost Report'!$H$5:$H$180,'Cost Report'!$A$5:$A$180,$A8) -> 8639590.5 | H8: =SUMIFS('Cost Report'!$I$5:$I$180,'Cost Report'!$A$5:$A$180,$A8) -> 6548600 | I8: =SUMIFS('Cost Report'!$M$5:$M$180,'Cost Report'!$A$5:$A$180,$A8) -> 8812195.1 | J8: =I8-G8 -> 172604.6 | K8: =IF(I8>0,G8/I8,0) -> 0.98041298 | L8: =E8*K8 -> 9960995.9 | M8: =SUMIFS(Data_Billings!$E:$E,Data_Billings!$D:$D,$A8) -> 10159341 | N8: =M8-L8 -> 198345.04 | O8: =E8-I8 -> 1347804.9 | P8: =IF(E8>0,O8/E8,0) -> 0.13265796 | Q8: =INDEX(Data_Jobs!$H:$H,MATCH($A8,Data_Jobs!$A:$A,0)) -> 0.12 | R8: =P8-Q8 -> 0.012657964 | S8: =IF(G8>0,SUMIFS('Cost Report'!$K$5:$K$180,'Cost Report'!$A$5:$A$180,$A8)/G8,"") -> 1.0293258 | T8: =E8-L8 -> 199004.07
A9: 25-110 | B9: =INDEX(Data_Jobs!$B:$B,MATCH($A9,Data_Jobs!$A:$A,0)) -> Medical Office Building | C9: =INDEX(Data_Jobs!$E:$E,MATCH($A9,Data_Jobs!$A:$A,0)) -> S. Chen | D9: =INDEX(Data_Jobs!$L:$L,MATCH($A9,Data_Jobs!$A:$A,0)) -> In progress | E9: =INDEX(Data_Jobs!$K:$K,MATCH($A9,Data_Jobs!$A:$A,0)) -> 25580000 | F9: =SUMIFS('Cost Report'!$G$5:$G$180,'Cost Report'!$A$5:$A$180,$A9) -> 22973200 | G9: =SUMIFS('Cost Report'!$H$5:$H$180,'Cost Report'!$A$5:$A$180,$A9) -> 15913660 | H9: =SUMIFS('Cost Report'!$I$5:$I$180,'Cost Report'!$A$5:$A$180,$A9) -> 18195100 | I9: =SUMIFS('Cost Report'!$M$5:$M$180,'Cost Report'!$A$5:$A$180,$A9) -> 23781711 | J9: =I9-G9 -> 7868051.1 | K9: =IF(I9>0,G9/I9,0) -> 0.66915539 | L9: =E9*K9 -> 17116995 | M9: =SUMIFS(Data_Billings!$E:$E,Data_Billings!$D:$D,$A9) -> 18511138 | N9: =M9-L9 -> 1394142.8 | O9: =E9-I9 -> 1798288.8 | P9: =IF(E9>0,O9/E9,0) -> 0.070300577 | Q9: =INDEX(Data_Jobs!$H:$H,MATCH($A9,Data_Jobs!$A:$A,0)) -> 0.1 | R9: =P9-Q9 -> -0.029699423 | S9: =IF(G9>0,SUMIFS('Cost Report'!$K$5:$K$180,'Cost Report'!$A$5:$A$180,$A9)/G9,"") -> 0.96603098 | T9: =E9-L9 -> 8463005.2
A10: 25-112 | B10: =INDEX(Data_Jobs!$B:$B,MATCH($A10,Data_Jobs!$A:$A,0)) -> Fire Hall No. 4 | C10: =INDEX(Data_Jobs!$E:$E,MATCH($A10,Data_Jobs!$A:$A,0)) -> R. Singh | D10: =INDEX(Data_Jobs!$L:$L,MATCH($A10,Data_Jobs!$A:$A,0)) -> In progress | E10: =INDEX(Data_Jobs!$K:$K,MATCH($A10,Data_Jobs!$A:$A,0)) -> 9026000 | F10: =SUMIFS('Cost Report'!$G$5:$G$180,'Cost Report'!$A$5:$A$180,$A10) -> 7983600 | G10: =SUMIFS('Cost Report'!$H$5:$H$180,'Cost Report'!$A$5:$A$180,$A10) -> 7797690.6 | H10: =SUMIFS('Cost Report'!$I$5:$I$180,'Cost Report'!$A$5:$A$180,$A10) -> 6175300 | I10: =SUMIFS('Cost Report'!$M$5:$M$180,'Cost Report'!$A$5:$A$180,$A10) -> 8177299.8 | J10: =I10-G10 -> 379609.19 | K10: =IF(I10>0,G10/I10,0) -> 0.95357768 | L10: =E10*K10 -> 8606992.2 | M10: =SUMIFS(Data_Billings!$E:$E,Data_Billings!$D:$D,$A10) -> 8359789.8 | N10: =M10-L10 -> -247202.33 | O10: =E10-I10 -> 848700.19 | P10: =IF(E10>0,O10/E10,0) -> 0.094028383 | Q10: =INDEX(Data_Jobs!$H:$H,MATCH($A10,Data_Jobs!$A:$A,0)) -> 0.115 | R10: =P10-Q10 -> -0.020971617 | S10: =IF(G10>0,SUMIFS('Cost Report'!$K$5:$K$180,'Cost Report'!$A$5:$A$180,$A10)/G10,"") -> 0.98619229 | T10: =E10-L10 -> 419007.82
A11: 25-115 | B11: =INDEX(Data_Jobs!$B:$B,MATCH($A11,Data_Jobs!$A:$A,0)) -> Recreation Centre Retrofit | C11: =INDEX(Data_Jobs!$E:$E,MATCH($A11,Data_Jobs!$A:$A,0)) -> J. Tremblay | D11: =INDEX(Data_Jobs!$L:$L,MATCH($A11,Data_Jobs!$A:$A,0)) -> In progress | E11: =INDEX(Data_Jobs!$K:$K,MATCH($A11,Data_Jobs!$A:$A,0)) -> 12065000 | F11: =SUMIFS('Cost Report'!$G$5:$G$180,'Cost Report'!$A$5:$A$180,$A11) -> 10763600 | G11: =SUMIFS('Cost Report'!$H$5:$H$180,'Cost Report'!$A$5:$A$180,$A11) -> 8582224.5 | H11: =SUMIFS('Cost Report'!$I$5:$I$180,'Cost Report'!$A$5:$A$180,$A11) -> 8139000 | I11: =SUMIFS('Cost Report'!$M$5:$M$180,'Cost Report'!$A$5:$A$180,$A11) -> 11519732 | J11: =I11-G11 -> 2937507.8 | K11: =IF(I11>0,G11/I11,0) -> 0.74500208 | L11: =E11*K11 -> 8988450.1 | M11: =SUMIFS(Data_Billings!$E:$E,Data_Billings!$D:$D,$A11) -> 8294926 | N11: =M11-L11 -> -693524.07 | O11: =E11-I11 -> 545267.72 | P11: =IF(E11>0,O11/E11,0) -> 0.045194175 | Q11: =INDEX(Data_Jobs!$H:$H,MATCH($A11,Data_Jobs!$A:$A,0)) -> 0.105 | R11: =P11-Q11 -> -0.059805825 | S11: =IF(G11>0,SUMIFS('Cost Report'!$K$5:$K$180,'Cost Report'!$A$5:$A$180,$A11)/G11,"") -> 0.94292272 | T11: =E11-L11 -> 3076549.9
A12: 25-118 | B12: =INDEX(Data_Jobs!$B:$B,MATCH($A12,Data_Jobs!$A:$A,0)) -> Cold Storage Facility | C12: =INDEX(Data_Jobs!$E:$E,MATCH($A12,Data_Jobs!$A:$A,0)) -> S. Chen | D12: =INDEX(Data_Jobs!$L:$L,MATCH($A12,Data_Jobs!$A:$A,0)) -> In progress | E12: =INDEX(Data_Jobs!$K:$K,MATCH($A12,Data_Jobs!$A:$A,0)) -> 18090000 | F12: =SUMIFS('Cost Report'!$G$5:$G$180,'Cost Report'!$A$5:$A$180,$A12) -> 16302200 | G12: =SUMIFS('Cost Report'!$H$5:$H$180,'Cost Report'!$A$5:$A$180,$A12) -> 13092124 | H12: =SUMIFS('Cost Report'!$I$5:$I$180,'Cost Report'!$A$5:$A$180,$A12) -> 12660900 | I12: =SUMIFS('Cost Report'!$M$5:$M$180,'Cost Report'!$A$5:$A$180,$A12) -> 16233743 | J12: =I12-G12 -> 3141619 | K12: =IF(I12>0,G12/I12,0) -> 0.80647599 | L12: =E12*K12 -> 14589151 | M12: =SUMIFS(Data_Billings!$E:$E,Data_Billings!$D:$D,$A12) -> 15322118 | N12: =M12-L12 -> 732967.53 | O12: =E12-I12 -> 1856257 | P12: =IF(E12>0,O12/E12,0) -> 0.10261233 | Q12: =INDEX(Data_Jobs!$H:$H,MATCH($A12,Data_Jobs!$A:$A,0)) -> 0.098 | R12: =P12-Q12 -> 0.0046123293 | S12: =IF(G12>0,SUMIFS('Cost Report'!$K$5:$K$180,'Cost Report'!$A$5:$A$180,$A12)/G12,"") -> 1.0181287 | T12: =E12-L12 -> 3500849.3
A13: 25-121 | B13: =INDEX(Data_Jobs!$B:$B,MATCH($A13,Data_Jobs!$A:$A,0)) -> Seniors Residence | C13: =INDEX(Data_Jobs!$E:$E,MATCH($A13,Data_Jobs!$A:$A,0)) -> A. Dubois | D13: =INDEX(Data_Jobs!$L:$L,MATCH($A13,Data_Jobs!$A:$A,0)) -> In progress | E13: =INDEX(Data_Jobs!$K:$K,MATCH($A13,Data_Jobs!$A:$A,0)) -> 20405000 | F13: =SUMIFS('Cost Report'!$G$5:$G$180,'Cost Report'!$A$5:$A$180,$A13) -> 18541400 | G13: =SUMIFS('Cost Report'!$H$5:$H$180,'Cost Report'!$A$5:$A$180,$A13) -> 5364879.5 | H13: =SUMIFS('Cost Report'!$I$5:$I$180,'Cost Report'!$A$5:$A$180,$A13) -> 13169200 | I13: =SUMIFS('Cost Report'!$M$5:$M$180,'Cost Report'!$A$5:$A$180,$A13) -> 18538819 | J13: =I13-G13 -> 13173939 | K13: =IF(I13>0,G13/I13,0) -> 0.28938626 | L13: =E13*K13 -> 5904926.7 | M13: =SUMIFS(Data_Billings!$E:$E,Data_Billings!$D:$D,$A13) -> 6001562.8 | N13: =M13-L13 -> 96636.089 | O13: =E13-I13 -> 1866181.2 | P13: =IF(E13>0,O13/E13,0) -> 0.091457054 | Q13: =INDEX(Data_Jobs!$H:$H,MATCH($A13,Data_Jobs!$A:$A,0)) -> 0.09 | R13: =P13-Q13 -> 0.0014570538 | S13: =IF(G13>0,SUMIFS('Cost Report'!$K$5:$K$180,'Cost Report'!$A$5:$A$180,$A13)/G13,"") -> 1.0143912 | T13: =E13-L13 -> 14500073
A14: 26-124 | B14: =INDEX(Data_Jobs!$B:$B,MATCH($A14,Data_Jobs!$A:$A,0)) -> Process Building | C14: =INDEX(Data_Jobs!$E:$E,MATCH($A14,Data_Jobs!$A:$A,0)) -> M. Okafor | D14: =INDEX(Data_Jobs!$L:$L,MATCH($A14,Data_Jobs!$A:$A,0)) -> In progress | E14: =INDEX(Data_Jobs!$K:$K,MATCH($A14,Data_Jobs!$A:$A,0)) -> 13400000 | F14: =SUMIFS('Cost Report'!$G$5:$G$180,'Cost Report'!$A$5:$A$180,$A14) -> 11858900 | G14: =SUMIFS('Cost Report'!$H$5:$H$180,'Cost Report'!$A$5:$A$180,$A14) -> 5372210.8 | H14: =SUMIFS('Cost Report'!$I$5:$I$180,'Cost Report'!$A$5:$A$180,$A14) -> 9211200 | I14: =SUMIFS('Cost Report'!$M$5:$M$180,'Cost Report'!$A$5:$A$180,$A14) -> 11951246 | J14: =I14-G14 -> 6579034.9 | K14: =IF(I14>0,G14/I14,0) -> 0.44951053 | L14: =E14*K14 -> 6023441.1 | M14: =SUMIFS(Data_Billings!$E:$E,Data_Billings!$D:$D,$A14) -> 6611526.6 | N14: =M14-L14 -> 588085.47 | O14: =E14-I14 -> 1448754.2 | P14: =IF(E14>0,O14/E14,0) -> 0.10811599 | Q14: =INDEX(Data_Jobs!$H:$H,MATCH($A14,Data_Jobs!$A:$A,0)) -> 0.115 | R14: =P14-Q14 -> -0.0068840141 | S14: =IF(G14>0,SUMIFS('Cost Report'!$K$5:$K$180,'Cost Report'!$A$5:$A$180,$A14)/G14,"") -> 0.99685378 | T14: =E14-L14 -> 7376558.9
A15: 26-127 | B15: =INDEX(Data_Jobs!$B:$B,MATCH($A15,Data_Jobs!$A:$A,0)) -> Retail Plaza | C15: =INDEX(Data_Jobs!$E:$E,MATCH($A15,Data_Jobs!$A:$A,0)) -> A. Dubois | D15: =INDEX(Data_Jobs!$L:$L,MATCH($A15,Data_Jobs!$A:$A,0)) -> In progress | E15: =INDEX(Data_Jobs!$K:$K,MATCH($A15,Data_Jobs!$A:$A,0)) -> 7650000 | F15: =SUMIFS('Cost Report'!$G$5:$G$180,'Cost Report'!$A$5:$A$180,$A15) -> 6693800 | G15: =SUMIFS('Cost Report'!$H$5:$H$180,'Cost Report'!$A$5:$A$180,$A15) -> 2201288.5 | H15: =SUMIFS('Cost Report'!$I$5:$I$180,'Cost Report'!$A$5:$A$180,$A15) -> 5000900 | I15: =SUMIFS('Cost Report'!$M$5:$M$180,'Cost Report'!$A$5:$A$180,$A15) -> 6607426.2 | J15: =I15-G15 -> 4406137.7 | K15: =IF(I15>0,G15/I15,0) -> 0.33315371 | L15: =E15*K15 -> 2548625.8 | M15: =SUMIFS(Data_Billings!$E:$E,Data_Billings!$D:$D,$A15) -> 2627509.3 | N15: =M15-L15 -> 78883.415 | O15: =E15-I15 -> 1042573.8 | P15: =IF(E15>0,O15/E15,0) -> 0.13628415 | Q15: =INDEX(Data_Jobs!$H:$H,MATCH($A15,Data_Jobs!$A:$A,0)) -> 0.125 | R15: =P15-Q15 -> 0.011284153 | S15: =IF(G15>0,SUMIFS('Cost Report'!$K$5:$K$180,'Cost Report'!$A$5:$A$180,$A15)/G15,"") -> 1.0346956 | T15: =E15-L15 -> 5101374.2
A16: 26-130 | B16: =INDEX(Data_Jobs!$B:$B,MATCH($A16,Data_Jobs!$A:$A,0)) -> Public Works Yard Building | C16: =INDEX(Data_Jobs!$E:$E,MATCH($A16,Data_Jobs!$A:$A,0)) -> R. Singh | D16: =INDEX(Data_Jobs!$L:$L,MATCH($A16,Data_Jobs!$A:$A,0)) -> In progress | E16: =INDEX(Data_Jobs!$K:$K,MATCH($A16,Data_Jobs!$A:$A,0)) -> 6300000 | F16: =SUMIFS('Cost Report'!$G$5:$G$180,'Cost Report'!$A$5:$A$180,$A16) -> 5607100 | G16: =SUMIFS('Cost Report'!$H$5:$H$180,'Cost Report'!$A$5:$A$180,$A16) -> 540737.58 | H16: =SUMIFS('Cost Report'!$I$5:$I$180,'Cost Report'!$A$5:$A$180,$A16) -> 3486800 | I16: =SUMIFS('Cost Report'!$M$5:$M$180,'Cost Report'!$A$5:$A$180,$A16) -> 5598962.3 | J16: =I16-G16 -> 5058224.7 | K16: =IF(I16>0,G16/I16,0) -> 0.096578179 | L16: =E16*K16 -> 608442.53 | M16: =SUMIFS(Data_Billings!$E:$E,Data_Billings!$D:$D,$A16) -> 614815.4 | N16: =M16-L16 -> 6372.8714 | O16: =E16-I16 -> 701037.74 | P16: =IF(E16>0,O16/E16,0) -> 0.11127583 | Q16: =INDEX(Data_Jobs!$H:$H,MATCH($A16,Data_Jobs!$A:$A,0)) -> 0.11 | R16: =P16-Q16 -> 0.001275832 | S16: =IF(G16>0,SUMIFS('Cost Report'!$K$5:$K$180,'Cost Report'!$A$5:$A$180,$A16)/G16,"") -> 1.0236786 | T16: =E16-L16 -> 5691557.5
A17: Portfolio total | E17: =SUM(E5:E16) -> 176921000 | F17: =SUM(F5:F16) -> 158253700 | G17: =SUM(G5:G16) -> 1.1457826e+08 | H17: =SUM(H5:H16) -> 120824700 | I17: =SUM(I5:I16) -> 1.608244e+08 | J17: =SUM(J5:J16) -> 46246134 | K17: =G17/I17 -> 0.7124433 | L17: =SUM(L5:L16) -> 1.2583805e+08 | M17: =SUM(M5:M16) -> 1.2825487e+08 | N17: =SUM(N5:N16) -> 2416818.1 | O17: =SUM(O5:O16) -> 16096602 | P17: =O17/E17 -> 0.090981862 | Q17: =SUMPRODUCT(Q5:Q16,E5:E16)/E17 -> 0.10421318 | R17: =P17-Q17 -> -0.013231318 | S17: ='Cost Report'!L181 -> 0.99250323 | T17: =SUM(T5:T16) -> 51082948
A19: Red: margin fade worse than -2.0 pts, or CPI below 0.97. Over/(under) billing: positive = billings in excess of revenue (liability); negative = revenue in excess of billings (asset).
A20: Green text = pulled from the job master (Data_Jobs). All other figures are formulas on the Cost Report and Data_ tabs.

Sheet Job Detail
A1: Job Cost Detail
A2: Pick a job number from the yellow drop-down to refresh this page.
B3: Job: | C3: 25-115 | D3: =INDEX(Data_Jobs!$B:$B,MATCH($C$3,Data_Jobs!$A:$A,0)) -> Recreation Centre Retrofit
C5: Project manager | D5: =INDEX(Data_Jobs!$E:$E,MATCH($C$3,Data_Jobs!$A:$A,0)) -> J. Tremblay | F5: Revised contract | H5: =INDEX(Data_Jobs!$K:$K,MATCH($C$3,Data_Jobs!$A:$A,0)) -> 12065000 | J5: Job CPI | M5: =IF(H27>0,K27/H27,0) -> 0.94292272
C6: Client type | D6: =INDEX(Data_Jobs!$D:$D,MATCH($C$3,Data_Jobs!$A:$A,0)) -> Municipal | F6: Forecast cost (EAC) | H6: =M27 -> 11519732 | J6: Labour productivity | M6: =IF(Q27>0,R27/Q27,0) -> 0.89317789
C7: Status | D7: =INDEX(Data_Jobs!$L:$L,MATCH($C$3,Data_Jobs!$A:$A,0)) -> In progress | F7: Projected margin | H7: =IF(H5>0,(H5-H6)/H5,0) -> 0.045194175 | J7: Forecast over budget | M7: =-SUMIF(N12:N26,"<0") -> 790532.28
C8: Scheduled finish | D8: =INDEX(Data_Jobs!$J:$J,MATCH($C$3,Data_Jobs!$A:$A,0)) -> 2027-03-26 | F8: Bid margin | H8: =INDEX(Data_Jobs!$H:$H,MATCH($C$3,Data_Jobs!$A:$A,0)) -> 0.105 | J8: Cost to complete | M8: =O27 -> 2937507.8
F9: Margin fade | H9: =H7-H8 -> -0.059805825
B11: Cost Code | C11: Description | D11: Cost Type | E11: Original Budget | F11: Budget Changes | G11: Revised Budget | H11: Actual Cost | I11: Committed | J11: % Complete | K11: Earned Value | L11: CPI | M11: Forecast Cost (EAC) | N11: Variance at Completion | O11: Cost to Complete | P11: Budget Hours | Q11: Actual Hours | R11: Earned Hours
B12: 01-100 | C12: =INDEX(Data_CostCodes!$B:$B,MATCH($B12,Data_CostCodes!$A:$A,0)) -> General Conditions - Supervision | D12: =INDEX(Data_CostCodes!$D:$D,MATCH($B12,Data_CostCodes!$A:$A,0)) -> Labour | E12: =SUMIFS('Cost Report'!$E$5:$E$180,'Cost Report'!$A$5:$A$180,$C$3,'Cost Report'!$B$5:$B$180,$B12) -> 957900 | F12: =SUMIFS('Cost Report'!$F$5:$F$180,'Cost Report'!$A$5:$A$180,$C$3,'Cost Report'!$B$5:$B$180,$B12) -> 0 | G12: =SUMIFS('Cost Report'!$G$5:$G$180,'Cost Report'!$A$5:$A$180,$C$3,'Cost Report'!$B$5:$B$180,$B12) -> 957900 | H12: =SUMIFS('Cost Report'!$H$5:$H$180,'Cost Report'!$A$5:$A$180,$C$3,'Cost Report'!$B$5:$B$180,$B12) -> 766276.35 | I12: =SUMIFS('Cost Report'!$I$5:$I$180,'Cost Report'!$A$5:$A$180,$C$3,'Cost Report'!$B$5:$B$180,$B12) -> 0 | J12: =IF(G12>0,K12/G12,0) -> 0.763 | K12: =SUMIFS('Cost Report'!$K$5:$K$180,'Cost Report'!$A$5:$A$180,$C$3,'Cost Report'!$B$5:$B$180,$B12) -> 730877.7 | L12: =IF(H12>0,K12/H12,"") -> 0.95380433 | M12: =SUMIFS('Cost Report'!$M$5:$M$180,'Cost Report'!$A$5:$A$180,$C$3,'Cost Report'!$B$5:$B$180,$B12) -> 1004294 | N12: =SUMIFS('Cost Report'!$N$5:$N$180,'Cost Report'!$A$5:$A$180,$C$3,'Cost Report'!$B$5:$B$180,$B12) -> -46394.037 | O12: =SUMIFS('Cost Report'!$O$5:$O$180,'Cost Report'!$A$5:$A$180,$C$3,'Cost Report'!$B$5:$B$180,$B12) -> 238017.69 | P12: =SUMIFS('Cost Report'!$P$5:$P$180,'Cost Report'!$A$5:$A$180,$C$3,'Cost Report'!$B$5:$B$180,$B12) -> 10412 | Q12: =SUMIFS('Cost Report'!$Q$5:$Q$180,'Cost Report'!$A$5:$A$180,$C$3,'Cost Report'!$B$5:$B$180,$B12) -> 8329 | R12: =SUMIFS('Cost Report'!$R$5:$R$180,'Cost Report'!$A$5:$A$180,$C$3,'Cost Report'!$B$5:$B$180,$B12) -> 7944.356
B13: 01-200 | C13: =INDEX(Data_CostCodes!$B:$B,MATCH($B13,Data_CostCodes!$A:$A,0)) -> Site Facilities & Temp Services | D13: =INDEX(Data_CostCodes!$D:$D,MATCH($B13,Data_CostCodes!$A:$A,0)) -> Other | E13: =SUMIFS('Cost Report'!$E$5:$E$180,'Cost Report'!$A$5:$A$180,$C$3,'Cost Report'!$B$5:$B$180,$B13) -> 313200 | F13: =SUMIFS('Cost Report'!$F$5:$F$180,'Cost Report'!$A$5:$A$180,$C$3,'Cost Report'!$B$5:$B$180,$B13) -> 43300 | G13: =SUMIFS('Cost Report'!$G$5:$G$180,'Cost Report'!$A$5:$A$180,$C$3,'Cost Report'!$B$5:$B$180,$B13) -> 356500 | H13: =SUMIFS('Cost Report'!$H$5:$H$180,'Cost Report'!$A$5:$A$180,$C$3,'Cost Report'!$B$5:$B$180,$B13) -> 275153.11 | I13: =SUMIFS('Cost Report'!$I$5:$I$180,'Cost Report'!$A$5:$A$180,$C$3,'Cost Report'!$B$5:$B$180,$B13) -> 0 | J13: =IF(G13>0,K13/G13,0) -> 0.743 | K13: =SUMIFS('Cost Report'!$K$5:$K$180,'Cost Report'!$A$5:$A$180,$C$3,'Cost Report'!$B$5:$B$180,$B13) -> 264879.5 | L13: =IF(H13>0,K13/H13,"") -> 0.96266221 | M13: =SUMIFS('Cost Report'!$M$5:$M$180,'Cost Report'!$A$5:$A$180,$C$3,'Cost Report'!$B$5:$B$180,$B13) -> 370327.2 | N13: =SUMIFS('Cost Report'!$N$5:$N$180,'Cost Report'!$A$5:$A$180,$C$3,'Cost Report'!$B$5:$B$180,$B13) -> -13827.201 | O13: =SUMIFS('Cost Report'!$O$5:$O$180,'Cost Report'!$A$5:$A$180,$C$3,'Cost Report'!$B$5:$B$180,$B13) -> 95174.091 | P13: =SUMIFS('Cost Report'!$P$5:$P$180,'Cost Report'!$A$5:$A$180,$C$3,'Cost Report'!$B$5:$B$180,$B13) -> 0 | Q13: =SUMIFS('Cost Report'!$Q$5:$Q$180,'Cost Report'!$A$5:$A$180,$C$3,'Cost Report'!$B$5:$B$180,$B13) -> 0 | R13: =SUMIFS('Cost Report'!$R$5:$R$180,'Cost Report'!$A$5:$A$180,$C$3,'Cost Report'!$B$5:$B$180,$B13) -> 0
B14: 01-500 | C14: =INDEX(Data_CostCodes!$B:$B,MATCH($B14,Data_CostCodes!$A:$A,0)) -> Equipment Rental | D14: =INDEX(Data_CostCodes!$D:$D,MATCH($B14,Data_CostCodes!$A:$A,0)) -> Equipment | E14: =SUMIFS('Cost Report'!$E$5:$E$180,'Cost Report'!$A$5:$A$180,$C$3,'Cost Report'!$B$5:$B$180,$B14) -> 275800 | F14: =SUMIFS('Cost Report'!$F$5:$F$180,'Cost Report'!$A$5:$A$180,$C$3,'Cost Report'!$B$5:$B$180,$B14) -> 0 | G14: =SUMIFS('Cost Report'!$G$5:$G$180,'Cost Report'!$A$5:$A$180,$C$3,'Cost Report'!$B$5:$B$180,$B14) -> 275800 | H14: =SUMIFS('Cost Report'!$H$5:$H$180,'Cost Report'!$A$5:$A$180,$C$3,'Cost Report'!$B$5:$B$180,$B14) -> 267801.12 | I14: =SUMIFS('Cost Report'!$I$5:$I$180,'Cost Report'!$A$5:$A$180,$C$3,'Cost Report'!$B$5:$B$180,$B14) -> 0 | J14: =IF(G14>0,K14/G14,0) -> 0.904 | K14: =SUMIFS('Cost Report'!$K$5:$K$180,'Cost Report'!$A$5:$A$180,$C$3,'Cost Report'!$B$5:$B$180,$B14) -> 249323.2 | L14: =IF(H14>0,K14/H14,"") -> 0.93100133 | M14: =SUMIFS('Cost Report'!$M$5:$M$180,'Cost Report'!$A$5:$A$180,$C$3,'Cost Report'!$B$5:$B$180,$B14) -> 296240.18 | N14: =SUMIFS('Cost Report'!$N$5:$N$180,'Cost Report'!$A$5:$A$180,$C$3,'Cost Report'!$B$5:$B$180,$B14) -> -20440.177 | O14: =SUMIFS('Cost Report'!$O$5:$O$180,'Cost Report'!$A$5:$A$180,$C$3,'Cost Report'!$B$5:$B$180,$B14) -> 28439.057 | P14: =SUMIFS('Cost Report'!$P$5:$P$180,'Cost Report'!$A$5:$A$180,$C$3,'Cost Report'!$B$5:$B$180,$B14) -> 0 | Q14: =SUMIFS('Cost Report'!$Q$5:$Q$180,'Cost Report'!$A$5:$A$180,$C$3,'Cost Report'!$B$5:$B$180,$B14) -> 0 | R14: =SUMIFS('Cost Report'!$R$5:$R$180,'Cost Report'!$A$5:$A$180,$C$3,'Cost Report'!$B$5:$B$180,$B14) -> 0
B15: 02-200 | C15: =INDEX(Data_CostCodes!$B:$B,MATCH($B15,Data_CostCodes!$A:$A,0)) -> Earthwork & Excavation | D15: =INDEX(Data_CostCodes!$D:$D,MATCH($B15,Data_CostCodes!$A:$A,0)) -> Subcontract | E15: =SUMIFS('Cost Report'!$E$5:$E$180,'Cost Report'!$A$5:$A$180,$C$3,'Cost Report'!$B$5:$B$180,$B15) -> 410500 | F15: =SUMIFS('Cost Report'!$F$5:$F$180,'Cost Report'!$A$5:$A$180,$C$3,'Cost Report'!$B$5:$B$180,$B15) -> 0 | G15: =SUMIFS('Cost Report'!$G$5:$G$180,'Cost Report'!$A$5:$A$180,$C$3,'Cost Report'!$B$5:$B$180,$B15) -> 410500 | H15: =SUMIFS('Cost Report'!$H$5:$H$180,'Cost Report'!$A$5:$A$180,$C$3,'Cost Report'!$B$5:$B$180,$B15) -> 395353.03 | I15: =SUMIFS('Cost Report'!$I$5:$I$180,'Cost Report'!$A$5:$A$180,$C$3,'Cost Report'!$B$5:$B$180,$B15) -> 396500 | J15: =IF(G15>0,K15/G15,0) -> 1 | K15: =SUMIFS('Cost Report'!$K$5:$K$180,'Cost Report'!$A$5:$A$180,$C$3,'Cost Report'!$B$5:$B$180,$B15) -> 410500 | L15: =IF(H15>0,K15/H15,"") -> 1.0383125 | M15: =SUMIFS('Cost Report'!$M$5:$M$180,'Cost Report'!$A$5:$A$180,$C$3,'Cost Report'!$B$5:$B$180,$B15) -> 396500 | N15: =SUMIFS('Cost Report'!$N$5:$N$180,'Cost Report'!$A$5:$A$180,$C$3,'Cost Report'!$B$5:$B$180,$B15) -> 14000 | O15: =SUMIFS('Cost Report'!$O$5:$O$180,'Cost Report'!$A$5:$A$180,$C$3,'Cost Report'!$B$5:$B$180,$B15) -> 1146.97 | P15: =SUMIFS('Cost Report'!$P$5:$P$180,'Cost Report'!$A$5:$A$180,$C$3,'Cost Report'!$B$5:$B$180,$B15) -> 0 | Q15: =SUMIFS('Cost Report'!$Q$5:$Q$180,'Cost Report'!$A$5:$A$180,$C$3,'Cost Report'!$B$5:$B$180,$B15) -> 0 | R15: =SUMIFS('Cost Report'!$R$5:$R$180,'Cost Report'!$A$5:$A$180,$C$3,'Cost Report'!$B$5:$B$180,$B15) -> 0
B16: 03-100 | C16: =INDEX(Data_CostCodes!$B:$B,MATCH($B16,Data_CostCodes!$A:$A,0)) -> Concrete Formwork | D16: =INDEX(Data_CostCodes!$D:$D,MATCH($B16,Data_CostCodes!$A:$A,0)) -> Labour | E16: =SUMIFS('Cost Report'!$E$5:$E$180,'Cost Report'!$A$5:$A$180,$C$3,'Cost Report'!$B$5:$B$180,$B16) -> 545200 | F16: =SUMIFS('Cost Report'!$F$5:$F$180,'Cost Report'!$A$5:$A$180,$C$3,'Cost Report'!$B$5:$B$180,$B16) -> 549300 | G16: =SUMIFS('Cost Report'!$G$5:$G$180,'Cost Report'!$A$5:$A$180,$C$3,'Cost Report'!$B$5:$B$180,$B16) -> 1094500 | H16: =SUMIFS('Cost Report'!$H$5:$H$180,'Cost Report'!$A$5:$A$180,$C$3,'Cost Report'!$B$5:$B$180,$B16) -> 1229218.8 | I16: =SUMIFS('Cost Report'!$I$5:$I$180,'Cost Report'!$A$5:$A$180,$C$3,'Cost Report'!$B$5:$B$180,$B16) -> 0 | J16: =IF(G16>0,K16/G16,0) -> 1 | K16: =SUMIFS('Cost Report'!$K$5:$K$180,'Cost Report'!$A$5:$A$180,$C$3,'Cost Report'!$B$5:$B$180,$B16) -> 1094500 | L16: =IF(H16>0,K16/H16,"") -> 0.89040289 | M16: =SUMIFS('Cost Report'!$M$5:$M$180,'Cost Report'!$A$5:$A$180,$C$3,'Cost Report'!$B$5:$B$180,$B16) -> 1229218.8 | N16: =SUMIFS('Cost Report'!$N$5:$N$180,'Cost Report'!$A$5:$A$180,$C$3,'Cost Report'!$B$5:$B$180,$B16) -> -134718.83 | O16: =SUMIFS('Cost Report'!$O$5:$O$180,'Cost Report'!$A$5:$A$180,$C$3,'Cost Report'!$B$5:$B$180,$B16) -> 0 | P16: =SUMIFS('Cost Report'!$P$5:$P$180,'Cost Report'!$A$5:$A$180,$C$3,'Cost Report'!$B$5:$B$180,$B16) -> 14791 | Q16: =SUMIFS('Cost Report'!$Q$5:$Q$180,'Cost Report'!$A$5:$A$180,$C$3,'Cost Report'!$B$5:$B$180,$B16) -> 16611.2 | R16: =SUMIFS('Cost Report'!$R$5:$R$180,'Cost Report'!$A$5:$A$180,$C$3,'Cost Report'!$B$5:$B$180,$B16) -> 14791
B17: 03-200 | C17: =INDEX(Data_CostCodes!$B:$B,MATCH($B17,Data_CostCodes!$A:$A,0)) -> Reinforcing Steel | D17: =INDEX(Data_CostCodes!$D:$D,MATCH($B17,Data_CostCodes!$A:$A,0)) -> Material | E17: =SUMIFS('Cost Report'!$E$5:$E$180,'Cost Report'!$A$5:$A$180,$C$3,'Cost Report'!$B$5:$B$180,$B17) -> 452600 | F17: =SUMIFS('Cost Report'!$F$5:$F$180,'Cost Report'!$A$5:$A$180,$C$3,'Cost Report'!$B$5:$B$180,$B17) -> 0 | G17: =SUMIFS('Cost Report'!$G$5:$G$180,'Cost Report'!$A$5:$A$180,$C$3,'Cost Report'!$B$5:$B$180,$B17) -> 452600 | H17: =SUMIFS('Cost Report'!$H$5:$H$180,'Cost Report'!$A$5:$A$180,$C$3,'Cost Report'!$B$5:$B$180,$B17) -> 446285.28 | I17: =SUMIFS('Cost Report'!$I$5:$I$180,'Cost Report'!$A$5:$A$180,$C$3,'Cost Report'!$B$5:$B$180,$B17) -> 456400 | J17: =IF(G17>0,K17/G17,0) -> 1 | K17: =SUMIFS('Cost Report'!$K$5:$K$180,'Cost Report'!$A$5:$A$180,$C$3,'Cost Report'!$B$5:$B$180,$B17) -> 452600 | L17: =IF(H17>0,K17/H17,"") -> 1.0141495 | M17: =SUMIFS('Cost Report'!$M$5:$M$180,'Cost Report'!$A$5:$A$180,$C$3,'Cost Report'!$B$5:$B$180,$B17) -> 456400 | N17: =SUMIFS('Cost Report'!$N$5:$N$180,'Cost Report'!$A$5:$A$180,$C$3,'Cost Report'!$B$5:$B$180,$B17) -> -3800 | O17: =SUMIFS('Cost Report'!$O$5:$O$180,'Cost Report'!$A$5:$A$180,$C$3,'Cost Report'!$B$5:$B$180,$B17) -> 10114.72 | P17: =SUMIFS('Cost Report'!$P$5:$P$180,'Cost Report'!$A$5:$A$180,$C$3,'Cost Report'!$B$5:$B$180,$B17) -> 0 | Q17: =SUMIFS('Cost Report'!$Q$5:$Q$180,'Cost Report'!$A$5:$A$180,$C$3,'Cost Report'!$B$5:$B$180,$B17) -> 0 | R17: =SUMIFS('Cost Report'!$R$5:$R$180,'Cost Report'!$A$5:$A$180,$C$3,'Cost Report'!$B$5:$B$180,$B17) -> 0
B18: 03-300 | C18: =INDEX(Data_CostCodes!$B:$B,MATCH($B18,Data_CostCodes!$A:$A,0)) -> Cast-in-Place Concrete | D18: =INDEX(Data_CostCodes!$D:$D,MATCH($B18,Data_CostCodes!$A:$A,0)) -> Material | E18: =SUMIFS('Cost Report'!$E$5:$E$180,'Cost Report'!$A$5:$A$180,$C$3,'Cost Report'!$B$5:$B$180,$B18) -> 763100 | F18: =SUMIFS('Cost Report'!$F$5:$F$180,'Cost Report'!$A$5:$A$180,$C$3,'Cost Report'!$B$5:$B$180,$B18) -> 0 | G18: =SUMIFS('Cost Report'!$G$5:$G$180,'Cost Report'!$A$5:$A$180,$C$3,'Cost Report'!$B$5:$B$180,$B18) -> 763100 | H18: =SUMIFS('Cost Report'!$H$5:$H$180,'Cost Report'!$A$5:$A$180,$C$3,'Cost Report'!$B$5:$B$180,$B18) -> 756596.67 | I18: =SUMIFS('Cost Report'!$I$5:$I$180,'Cost Report'!$A$5:$A$180,$C$3,'Cost Report'!$B$5:$B$180,$B18) -> 767600 | J18: =IF(G18>0,K18/G18,0) -> 1 | K18: =SUMIFS('Cost Report'!$K$5:$K$180,'Cost Report'!$A$5:$A$180,$C$3,'Cost Report'!$B$5:$B$180,$B18) -> 763100 | L18: =IF(H18>0,K18/H18,"") -> 1.0085955 | M18: =SUMIFS('Cost Report'!$M$5:$M$180,'Cost Report'!$A$5:$A$180,$C$3,'Cost Report'!$B$5:$B$180,$B18) -> 767600 | N18: =SUMIFS('Cost Report'!$N$5:$N$180,'Cost Report'!$A$5:$A$180,$C$3,'Cost Report'!$B$5:$B$180,$B18) -> -4500 | O18: =SUMIFS('Cost Report'!$O$5:$O$180,'Cost Report'!$A$5:$A$180,$C$3,'Cost Report'!$B$5:$B$180,$B18) -> 11003.33 | P18: =SUMIFS('Cost Report'!$P$5:$P$180,'Cost Report'!$A$5:$A$180,$C$3,'Cost Report'!$B$5:$B$180,$B18) -> 0 | Q18: =SUMIFS('Cost Report'!$Q$5:$Q$180,'Cost Report'!$A$5:$A$180,$C$3,'Cost Report'!$B$5:$B$180,$B18) -> 0 | R18: =SUMIFS('Cost Report'!$R$5:$R$180,'Cost Report'!$A$5:$A$180,$C$3,'Cost Report'!$B$5:$B$180,$B18) -> 0
B19: 04-200 | C19: =INDEX(Data_CostCodes!$B:$B,MATCH($B19,Data_CostCodes!$A:$A,0)) -> Masonry | D19: =INDEX(Data_CostCodes!$D:$D,MATCH($B19,Data_CostCodes!$A:$A,0)) -> Subcontract | E19: =SUMIFS('Cost Report'!$E$5:$E$180,'Cost Report'!$A$5:$A$180,$C$3,'Cost Report'!$B$5:$B$180,$B19) -> 789900 | F19: =SUMIFS('Cost Report'!$F$5:$F$180,'Cost Report'!$A$5:$A$180,$C$3,'Cost Report'!$B$5:$B$180,$B19) -> 0 | G19: =SUMIFS('Cost Report'!$G$5:$G$180,'Cost Report'!$A$5:$A$180,$C$3,'Cost Report'!$B$5:$B$180,$B19) -> 789900 | H19: =SUMIFS('Cost Report'!$H$5:$H$180,'Cost Report'!$A$5:$A$180,$C$3,'Cost Report'!$B$5:$B$180,$B19) -> 808032.22 | I19: =SUMIFS('Cost Report'!$I$5:$I$180,'Cost Report'!$A$5:$A$180,$C$3,'Cost Report'!$B$5:$B$180,$B19) -> 811100 | J19: =IF(G19>0,K19/G19,0) -> 1 | K19: =SUMIFS('Cost Report'!$K$5:$K$180,'Cost Report'!$A$5:$A$180,$C$3,'Cost Report'!$B$5:$B$180,$B19) -> 789900 | L19: =IF(H19>0,K19/H19,"") -> 0.97756003 | M19: =SUMIFS('Cost Report'!$M$5:$M$180,'Cost Report'!$A$5:$A$180,$C$3,'Cost Report'!$B$5:$B$180,$B19) -> 811100 | N19: =SUMIFS('Cost Report'!$N$5:$N$180,'Cost Report'!$A$5:$A$180,$C$3,'Cost Report'!$B$5:$B$180,$B19) -> -21200 | O19: =SUMIFS('Cost Report'!$O$5:$O$180,'Cost Report'!$A$5:$A$180,$C$3,'Cost Report'!$B$5:$B$180,$B19) -> 3067.78 | P19: =SUMIFS('Cost Report'!$P$5:$P$180,'Cost Report'!$A$5:$A$180,$C$3,'Cost Report'!$B$5:$B$180,$B19) -> 0 | Q19: =SUMIFS('Cost Report'!$Q$5:$Q$180,'Cost Report'!$A$5:$A$180,$C$3,'Cost Report'!$B$5:$B$180,$B19) -> 0 | R19: =SUMIFS('Cost Report'!$R$5:$R$180,'Cost Report'!$A$5:$A$180,$C$3,'Cost Report'!$B$5:$B$180,$B19) -> 0
B20: 05-100 | C20: =INDEX(Data_CostCodes!$B:$B,MATCH($B20,Data_CostCodes!$A:$A,0)) -> Structural Steel | D20: =INDEX(Data_CostCodes!$D:$D,MATCH($B20,Data_CostCodes!$A:$A,0)) -> Subcontract | E20: =SUMIFS('Cost Report'!$E$5:$E$180,'Cost Report'!$A$5:$A$180,$C$3,'Cost Report'!$B$5:$B$180,$B20) -> 730300 | F20: =SUMIFS('Cost Report'!$F$5:$F$180,'Cost Report'!$A$5:$A$180,$C$3,'Cost Report'!$B$5:$B$180,$B20) -> 0 | G20: =SUMIFS('Cost Report'!$G$5:$G$180,'Cost Report'!$A$5:$A$180,$C$3,'Cost Report'!$B$5:$B$180,$B20) -> 730300 | H20: =SUMIFS('Cost Report'!$H$5:$H$180,'Cost Report'!$A$5:$A$180,$C$3,'Cost Report'!$B$5:$B$180,$B20) -> 731077.8 | I20: =SUMIFS('Cost Report'!$I$5:$I$180,'Cost Report'!$A$5:$A$180,$C$3,'Cost Report'!$B$5:$B$180,$B20) -> 735800 | J20: =IF(G20>0,K20/G20,0) -> 1 | K20: =SUMIFS('Cost Report'!$K$5:$K$180,'Cost Report'!$A$5:$A$180,$C$3,'Cost Report'!$B$5:$B$180,$B20) -> 730300 | L20: =IF(H20>0,K20/H20,"") -> 0.99893609 | M20: =SUMIFS('Cost Report'!$M$5:$M$180,'Cost Report'!$A$5:$A$180,$C$3,'Cost Report'!$B$5:$B$180,$B20) -> 735800 | N20: =SUMIFS('Cost Report'!$N$5:$N$180,'Cost Report'!$A$5:$A$180,$C$3,'Cost Report'!$B$5:$B$180,$B20) -> -5500 | O20: =SUMIFS('Cost Report'!$O$5:$O$180,'Cost Report'!$A$5:$A$180,$C$3,'Cost Report'!$B$5:$B$180,$B20) -> 4722.2 | P20: =SUMIFS('Cost Report'!$P$5:$P$180,'Cost Report'!$A$5:$A$180,$C$3,'Cost Report'!$B$5:$B$180,$B20) -> 0 | Q20: =SUMIFS('Cost Report'!$Q$5:$Q$180,'Cost Report'!$A$5:$A$180,$C$3,'Cost Report'!$B$5:$B$180,$B20) -> 0 | R20: =SUMIFS('Cost Report'!$R$5:$R$180,'Cost Report'!$A$5:$A$180,$C$3,'Cost Report'!$B$5:$B$180,$B20) -> 0
B21: 06-100 | C21: =INDEX(Data_CostCodes!$B:$B,MATCH($B21,Data_CostCodes!$A:$A,0)) -> Rough Carpentry | D21: =INDEX(Data_CostCodes!$D:$D,MATCH($B21,Data_CostCodes!$A:$A,0)) -> Labour | E21: =SUMIFS('Cost Report'!$E$5:$E$180,'Cost Report'!$A$5:$A$180,$C$3,'Cost Report'!$B$5:$B$180,$B21) -> 385900 | F21: =SUMIFS('Cost Report'!$F$5:$F$180,'Cost Report'!$A$5:$A$180,$C$3,'Cost Report'!$B$5:$B$180,$B21) -> 0 | G21: =SUMIFS('Cost Report'!$G$5:$G$180,'Cost Report'!$A$5:$A$180,$C$3,'Cost Report'!$B$5:$B$180,$B21) -> 385900 | H21: =SUMIFS('Cost Report'!$H$5:$H$180,'Cost Report'!$A$5:$A$180,$C$3,'Cost Report'!$B$5:$B$180,$B21) -> 360969.68 | I21: =SUMIFS('Cost Report'!$I$5:$I$180,'Cost Report'!$A$5:$A$180,$C$3,'Cost Report'!$B$5:$B$180,$B21) -> 0 | J21: =IF(G21>0,K21/G21,0) -> 0.751 | K21: =SUMIFS('Cost Report'!$K$5:$K$180,'Cost Report'!$A$5:$A$180,$C$3,'Cost Report'!$B$5:$B$180,$B21) -> 289810.9 | L21: =IF(H21>0,K21/H21,"") -> 0.80286771 | M21: =SUMIFS('Cost Report'!$M$5:$M$180,'Cost Report'!$A$5:$A$180,$C$3,'Cost Report'!$B$5:$B$180,$B21) -> 480652.04 | N21: =SUMIFS('Cost Report'!$N$5:$N$180,'Cost Report'!$A$5:$A$180,$C$3,'Cost Report'!$B$5:$B$180,$B21) -> -94752.037 | O21: =SUMIFS('Cost Report'!$O$5:$O$180,'Cost Report'!$A$5:$A$180,$C$3,'Cost Report'!$B$5:$B$180,$B21) -> 119682.36 | P21: =SUMIFS('Cost Report'!$P$5:$P$180,'Cost Report'!$A$5:$A$180,$C$3,'Cost Report'!$B$5:$B$180,$B21) -> 5435 | Q21: =SUMIFS('Cost Report'!$Q$5:$Q$180,'Cost Report'!$A$5:$A$180,$C$3,'Cost Report'!$B$5:$B$180,$B21) -> 5084.1 | R21: =SUMIFS('Cost Report'!$R$5:$R$180,'Cost Report'!$A$5:$A$180,$C$3,'Cost Report'!$B$5:$B$180,$B21) -> 4081.685
B22: 07-200 | C22: =INDEX(Data_CostCodes!$B:$B,MATCH($B22,Data_CostCodes!$A:$A,0)) -> Roofing & Insulation | D22: =INDEX(Data_CostCodes!$D:$D,MATCH($B22,Data_CostCodes!$A:$A,0)) -> Subcontract | E22: =SUMIFS('Cost Report'!$E$5:$E$180,'Cost Report'!$A$5:$A$180,$C$3,'Cost Report'!$B$5:$B$180,$B22) -> 647300 | F22: =SUMIFS('Cost Report'!$F$5:$F$180,'Cost Report'!$A$5:$A$180,$C$3,'Cost Report'!$B$5:$B$180,$B22) -> 57600 | G22: =SUMIFS('Cost Report'!$G$5:$G$180,'Cost Report'!$A$5:$A$180,$C$3,'Cost Report'!$B$5:$B$180,$B22) -> 704900 | H22: =SUMIFS('Cost Report'!$H$5:$H$180,'Cost Report'!$A$5:$A$180,$C$3,'Cost Report'!$B$5:$B$180,$B22) -> 657408.01 | I22: =SUMIFS('Cost Report'!$I$5:$I$180,'Cost Report'!$A$5:$A$180,$C$3,'Cost Report'!$B$5:$B$180,$B22) -> 705400 | J22: =IF(G22>0,K22/G22,0) -> 0.954 | K22: =SUMIFS('Cost Report'!$K$5:$K$180,'Cost Report'!$A$5:$A$180,$C$3,'Cost Report'!$B$5:$B$180,$B22) -> 672474.6 | L22: =IF(H22>0,K22/H22,"") -> 1.0229182 | M22: =SUMIFS('Cost Report'!$M$5:$M$180,'Cost Report'!$A$5:$A$180,$C$3,'Cost Report'!$B$5:$B$180,$B22) -> 705400 | N22: =SUMIFS('Cost Report'!$N$5:$N$180,'Cost Report'!$A$5:$A$180,$C$3,'Cost Report'!$B$5:$B$180,$B22) -> -500 | O22: =SUMIFS('Cost Report'!$O$5:$O$180,'Cost Report'!$A$5:$A$180,$C$3,'Cost Report'!$B$5:$B$180,$B22) -> 47991.99 | P22: =SUMIFS('Cost Report'!$P$5:$P$180,'Cost Report'!$A$5:$A$180,$C$3,'Cost Report'!$B$5:$B$180,$B22) -> 0 | Q22: =SUMIFS('Cost Report'!$Q$5:$Q$180,'Cost Report'!$A$5:$A$180,$C$3,'Cost Report'!$B$5:$B$180,$B22) -> 0 | R22: =SUMIFS('Cost Report'!$R$5:$R$180,'Cost Report'!$A$5:$A$180,$C$3,'Cost Report'!$B$5:$B$180,$B22) -> 0
B23: 08-100 | C23: =INDEX(Data_CostCodes!$B:$B,MATCH($B23,Data_CostCodes!$A:$A,0)) -> Doors, Frames & Hardware | D23: =INDEX(Data_CostCodes!$D:$D,MATCH($B23,Data_CostCodes!$A:$A,0)) -> Material | E23: =SUMIFS('Cost Report'!$E$5:$E$180,'Cost Report'!$A$5:$A$180,$C$3,'Cost Report'!$B$5:$B$180,$B23) -> 438400 | F23: =SUMIFS('Cost Report'!$F$5:$F$180,'Cost Report'!$A$5:$A$180,$C$3,'Cost Report'!$B$5:$B$180,$B23) -> 0 | G23: =SUMIFS('Cost Report'!$G$5:$G$180,'Cost Report'!$A$5:$A$180,$C$3,'Cost Report'!$B$5:$B$180,$B23) -> 438400 | H23: =SUMIFS('Cost Report'!$H$5:$H$180,'Cost Report'!$A$5:$A$180,$C$3,'Cost Report'!$B$5:$B$180,$B23) -> 46792.64 | I23: =SUMIFS('Cost Report'!$I$5:$I$180,'Cost Report'!$A$5:$A$180,$C$3,'Cost Report'!$B$5:$B$180,$B23) -> 430700 | J23: =IF(G23>0,K23/G23,0) -> 0.11 | K23: =SUMIFS('Cost Report'!$K$5:$K$180,'Cost Report'!$A$5:$A$180,$C$3,'Cost Report'!$B$5:$B$180,$B23) -> 48224 | L23: =IF(H23>0,K23/H23,"") -> 1.0305894 | M23: =SUMIFS('Cost Report'!$M$5:$M$180,'Cost Report'!$A$5:$A$180,$C$3,'Cost Report'!$B$5:$B$180,$B23) -> 430700 | N23: =SUMIFS('Cost Report'!$N$5:$N$180,'Cost Report'!$A$5:$A$180,$C$3,'Cost Report'!$B$5:$B$180,$B23) -> 7700 | O23: =SUMIFS('Cost Report'!$O$5:$O$180,'Cost Report'!$A$5:$A$180,$C$3,'Cost Report'!$B$5:$B$180,$B23) -> 383907.36 | P23: =SUMIFS('Cost Report'!$P$5:$P$180,'Cost Report'!$A$5:$A$180,$C$3,'Cost Report'!$B$5:$B$180,$B23) -> 0 | Q23: =SUMIFS('Cost Report'!$Q$5:$Q$180,'Cost Report'!$A$5:$A$180,$C$3,'Cost Report'!$B$5:$B$180,$B23) -> 0 | R23: =SUMIFS('Cost Report'!$R$5:$R$180,'Cost Report'!$A$5:$A$180,$C$3,'Cost Report'!$B$5:$B$180,$B23) -> 0
... B26: 16-000 | C26: =INDEX(Data_CostCodes!$B:$B,MATCH($B26,Data_CostCodes!$A:$A,0)) -> Electrical | D26: =INDEX(Data_CostCodes!$D:$D,MATCH($B26,Data_CostCodes!$A:$A,0)) -> Subcontract | E26: =SUMIFS('Cost Report'!$E$5:$E$180,'Cost Report'!$A$5:$A$180,$C$3,'Cost Report'!$B$5:$B$180,$B26) -> 1065000 | F26: =SUMIFS('Cost Report'!$F$5:$F$180,'Cost Report'!$A$5:$A$180,$C$3,'Cost Report'!$B$5:$B$180,$B26) -> 0 | G26: =SUMIFS('Cost Report'!$G$5:$G$180,'Cost Report'!$A$5:$A$180,$C$3,'Cost Report'!$B$5:$B$180,$B26) -> 1065000 | H26: =SUMIFS('Cost Report'!$H$5:$H$180,'Cost Report'!$A$5:$A$180,$C$3,'Cost Report'!$B$5:$B$180,$B26) -> 608567.8 | I26: =SUMIFS('Cost Report'!$I$5:$I$180,'Cost Report'!$A$5:$A$180,$C$3,'Cost Report'!$B$5:$B$180,$B26) -> 1052300 | J26: =IF(G26>0,K26/G26,0) -> 0.587 | K26: =SUMIFS('Cost Report'!$K$5:$K$180,'Cost Report'!$A$5:$A$180,$C$3,'Cost Report'!$B$5:$B$180,$B26) -> 625155 | L26: =IF(H26>0,K26/H26,"") -> 1.0272561 | M26: =SUMIFS('Cost Report'!$M$5:$M$180,'Cost Report'!$A$5:$A$180,$C$3,'Cost Report'!$B$5:$B$180,$B26) -> 1052300 | N26: =SUMIFS('Cost Report'!$N$5:$N$180,'Cost Report'!$A$5:$A$180,$C$3,'Cost Report'!$B$5:$B$180,$B26) -> 12700 | O26: =SUMIFS('Cost Report'!$O$5:$O$180,'Cost Report'!$A$5:$A$180,$C$3,'Cost Report'!$B$5:$B$180,$B26) -> 443732.2 | P26: =SUMIFS('Cost Report'!$P$5:$P$180,'Cost Report'!$A$5:$A$180,$C$3,'Cost Report'!$B$5:$B$180,$B26) -> 0 | Q26: =SUMIFS('Cost Report'!$Q$5:$Q$180,'Cost Report'!$A$5:$A$180,$C$3,'Cost Report'!$B$5:$B$180,$B26) -> 0 | R26: =SUMIFS('Cost Report'!$R$5:$R$180,'Cost Report'!$A$5:$A$180,$C$3,'Cost Report'!$B$5:$B$180,$B26) -> 0
B27: Job total | E27: =SUM(E12:E26) -> 10113400 | F27: =SUM(F12:F26) -> 650200 | G27: =SUM(G12:G26) -> 10763600 | H27: =SUM(H12:H26) -> 8582224.5 | I27: =SUM(I12:I26) -> 8139000 | J27: =IF(G27>0,K27/G27,0) -> 0.75182787 | K27: =SUM(K12:K26) -> 8092374.5 | L27: =IF(H27>0,K27/H27,0) -> 0.94292272 | M27: =SUM(M12:M26) -> 11519732 | N27: =SUM(N12:N26) -> -756132.28 | O27: =SUM(O12:O26) -> 2937507.8 | P27: =SUM(P12:P26) -> 30638 | Q27: =SUM(Q12:Q26) -> 30024.3 | R27: =SUM(R12:R26) -> 26817.041
B29: Cost codes not used on the selected job show as '-'. Red: forecast overrun above $25,000 or CPI below 0.95.

Sheet Monthly Cost
A1: Monthly Job Cost
A2: Posted cost by fiscal period from the job cost ledger (Data_JobCost).
A4: Period | B4: 23-098 | C4: 24-101 | D4: 24-104 | E4: 24-107 | F4: 25-110 | G4: 25-112 | H4: 25-115 | I4: 25-118 | J4: 25-121 | K4: 26-124 | L4: 26-127 | M4: 26-130 | N4: Portfolio | O4: Cumulative
A5: 202406 | B5: =SUMIFS(Data_JobCost!$L:$L,Data_JobCost!$C:$C,$A5,Data_JobCost!$D:$D,B$4) -> 39201.02 | C5: =SUMIFS(Data_JobCost!$L:$L,Data_JobCost!$C:$C,$A5,Data_JobCost!$D:$D,C$4) -> 0 | D5: =SUMIFS(Data_JobCost!$L:$L,Data_JobCost!$C:$C,$A5,Data_JobCost!$D:$D,D$4) -> 0 | E5: =SUMIFS(Data_JobCost!$L:$L,Data_JobCost!$C:$C,$A5,Data_JobCost!$D:$D,E$4) -> 0 | F5: =SUMIFS(Data_JobCost!$L:$L,Data_JobCost!$C:$C,$A5,Data_JobCost!$D:$D,F$4) -> 0 | G5: =SUMIFS(Data_JobCost!$L:$L,Data_JobCost!$C:$C,$A5,Data_JobCost!$D:$D,G$4) -> 0 | H5: =SUMIFS(Data_JobCost!$L:$L,Data_JobCost!$C:$C,$A5,Data_JobCost!$D:$D,H$4) -> 0 | I5: =SUMIFS(Data_JobCost!$L:$L,Data_JobCost!$C:$C,$A5,Data_JobCost!$D:$D,I$4) -> 0 | ... M5: =SUMIFS(Data_JobCost!$L:$L,Data_JobCost!$C:$C,$A5,Data_JobCost!$D:$D,M$4) -> 0 | N5: =SUM(B5:M5) -> 39201.02 | O5: =N5 -> 39201.02
A6: 202407 | B6: =SUMIFS(Data_JobCost!$L:$L,Data_JobCost!$C:$C,$A6,Data_JobCost!$D:$D,B$4) -> 91276.61 | C6: =SUMIFS(Data_JobCost!$L:$L,Data_JobCost!$C:$C,$A6,Data_JobCost!$D:$D,C$4) -> 0 | D6: =SUMIFS(Data_JobCost!$L:$L,Data_JobCost!$C:$C,$A6,Data_JobCost!$D:$D,D$4) -> 0 | E6: =SUMIFS(Data_JobCost!$L:$L,Data_JobCost!$C:$C,$A6,Data_JobCost!$D:$D,E$4) -> 0 | F6: =SUMIFS(Data_JobCost!$L:$L,Data_JobCost!$C:$C,$A6,Data_JobCost!$D:$D,F$4) -> 0 | G6: =SUMIFS(Data_JobCost!$L:$L,Data_JobCost!$C:$C,$A6,Data_JobCost!$D:$D,G$4) -> 0 | H6: =SUMIFS(Data_JobCost!$L:$L,Data_JobCost!$C:$C,$A6,Data_JobCost!$D:$D,H$4) -> 0 | I6: =SUMIFS(Data_JobCost!$L:$L,Data_JobCost!$C:$C,$A6,Data_JobCost!$D:$D,I$4) -> 0 | ... M6: =SUMIFS(Data_JobCost!$L:$L,Data_JobCost!$C:$C,$A6,Data_JobCost!$D:$D,M$4) -> 0 | N6: =SUM(B6:M6) -> 91276.61 | O6: =O5+N6 -> 130477.63
A7: 202408 | B7: =SUMIFS(Data_JobCost!$L:$L,Data_JobCost!$C:$C,$A7,Data_JobCost!$D:$D,B$4) -> 184236.51 | C7: =SUMIFS(Data_JobCost!$L:$L,Data_JobCost!$C:$C,$A7,Data_JobCost!$D:$D,C$4) -> 0 | D7: =SUMIFS(Data_JobCost!$L:$L,Data_JobCost!$C:$C,$A7,Data_JobCost!$D:$D,D$4) -> 0 | E7: =SUMIFS(Data_JobCost!$L:$L,Data_JobCost!$C:$C,$A7,Data_JobCost!$D:$D,E$4) -> 0 | F7: =SUMIFS(Data_JobCost!$L:$L,Data_JobCost!$C:$C,$A7,Data_JobCost!$D:$D,F$4) -> 0 | G7: =SUMIFS(Data_JobCost!$L:$L,Data_JobCost!$C:$C,$A7,Data_JobCost!$D:$D,G$4) -> 0 | H7: =SUMIFS(Data_JobCost!$L:$L,Data_JobCost!$C:$C,$A7,Data_JobCost!$D:$D,H$4) -> 0 | I7: =SUMIFS(Data_JobCost!$L:$L,Data_JobCost!$C:$C,$A7,Data_JobCost!$D:$D,I$4) -> 0 | ... M7: =SUMIFS(Data_JobCost!$L:$L,Data_JobCost!$C:$C,$A7,Data_JobCost!$D:$D,M$4) -> 0 | N7: =SUM(B7:M7) -> 184236.51 | O7: =O6+N7 -> 314714.14
A8: 202409 | B8: =SUMIFS(Data_JobCost!$L:$L,Data_JobCost!$C:$C,$A8,Data_JobCost!$D:$D,B$4) -> 245464.58 | C8: =SUMIFS(Data_JobCost!$L:$L,Data_JobCost!$C:$C,$A8,Data_JobCost!$D:$D,C$4) -> 0 | D8: =SUMIFS(Data_JobCost!$L:$L,Data_JobCost!$C:$C,$A8,Data_JobCost!$D:$D,D$4) -> 0 | E8: =SUMIFS(Data_JobCost!$L:$L,Data_JobCost!$C:$C,$A8,Data_JobCost!$D:$D,E$4) -> 0 | F8: =SUMIFS(Data_JobCost!$L:$L,Data_JobCost!$C:$C,$A8,Data_JobCost!$D:$D,F$4) -> 0 | G8: =SUMIFS(Data_JobCost!$L:$L,Data_JobCost!$C:$C,$A8,Data_JobCost!$D:$D,G$4) -> 0 | H8: =SUMIFS(Data_JobCost!$L:$L,Data_JobCost!$C:$C,$A8,Data_JobCost!$D:$D,H$4) -> 0 | I8: =SUMIFS(Data_JobCost!$L:$L,Data_JobCost!$C:$C,$A8,Data_JobCost!$D:$D,I$4) -> 0 | ... M8: =SUMIFS(Data_JobCost!$L:$L,Data_JobCost!$C:$C,$A8,Data_JobCost!$D:$D,M$4) -> 0 | N8: =SUM(B8:M8) -> 245464.58 | O8: =O7+N8 -> 560178.72
A9: 202410 | B9: =SUMIFS(Data_JobCost!$L:$L,Data_JobCost!$C:$C,$A9,Data_JobCost!$D:$D,B$4) -> 342893.6 | C9: =SUMIFS(Data_JobCost!$L:$L,Data_JobCost!$C:$C,$A9,Data_JobCost!$D:$D,C$4) -> 0 | D9: =SUMIFS(Data_JobCost!$L:$L,Data_JobCost!$C:$C,$A9,Data_JobCost!$D:$D,D$4) -> 0 | E9: =SUMIFS(Data_JobCost!$L:$L,Data_JobCost!$C:$C,$A9,Data_JobCost!$D:$D,E$4) -> 0 | F9: =SUMIFS(Data_JobCost!$L:$L,Data_JobCost!$C:$C,$A9,Data_JobCost!$D:$D,F$4) -> 0 | G9: =SUMIFS(Data_JobCost!$L:$L,Data_JobCost!$C:$C,$A9,Data_JobCost!$D:$D,G$4) -> 0 | H9: =SUMIFS(Data_JobCost!$L:$L,Data_JobCost!$C:$C,$A9,Data_JobCost!$D:$D,H$4) -> 0 | I9: =SUMIFS(Data_JobCost!$L:$L,Data_JobCost!$C:$C,$A9,Data_JobCost!$D:$D,I$4) -> 0 | ... M9: =SUMIFS(Data_JobCost!$L:$L,Data_JobCost!$C:$C,$A9,Data_JobCost!$D:$D,M$4) -> 0 | N9: =SUM(B9:M9) -> 342893.6 | O9: =O8+N9 -> 903072.32
A10: 202411 | B10: =SUMIFS(Data_JobCost!$L:$L,Data_JobCost!$C:$C,$A10,Data_JobCost!$D:$D,B$4) -> 384273.5 | C10: =SUMIFS(Data_JobCost!$L:$L,Data_JobCost!$C:$C,$A10,Data_JobCost!$D:$D,C$4) -> 0 | D10: =SUMIFS(Data_JobCost!$L:$L,Data_JobCost!$C:$C,$A10,Data_JobCost!$D:$D,D$4) -> 0 | E10: =SUMIFS(Data_JobCost!$L:$L,Data_JobCost!$C:$C,$A10,Data_JobCost!$D:$D,E$4) -> 0 | F10: =SUMIFS(Data_JobCost!$L:$L,Data_JobCost!$C:$C,$A10,Data_JobCost!$D:$D,F$4) -> 0 | G10: =SUMIFS(Data_JobCost!$L:$L,Data_JobCost!$C:$C,$A10,Data_JobCost!$D:$D,G$4) -> 0 | H10: =SUMIFS(Data_JobCost!$L:$L,Data_JobCost!$C:$C,$A10,Data_JobCost!$D:$D,H$4) -> 0 | I10: =SUMIFS(Data_JobCost!$L:$L,Data_JobCost!$C:$C,$A10,Data_JobCost!$D:$D,I$4) -> 0 | ... M10: =SUMIFS(Data_JobCost!$L:$L,Data_JobCost!$C:$C,$A10,Data_JobCost!$D:$D,M$4) -> 0 | N10: =SUM(B10:M10) -> 384273.5 | O10: =O9+N10 -> 1287345.8
A11: 202412 | B11: =SUMIFS(Data_JobCost!$L:$L,Data_JobCost!$C:$C,$A11,Data_JobCost!$D:$D,B$4) -> 438101.97 | C11: =SUMIFS(Data_JobCost!$L:$L,Data_JobCost!$C:$C,$A11,Data_JobCost!$D:$D,C$4) -> 0 | D11: =SUMIFS(Data_JobCost!$L:$L,Data_JobCost!$C:$C,$A11,Data_JobCost!$D:$D,D$4) -> 0 | E11: =SUMIFS(Data_JobCost!$L:$L,Data_JobCost!$C:$C,$A11,Data_JobCost!$D:$D,E$4) -> 0 | F11: =SUMIFS(Data_JobCost!$L:$L,Data_JobCost!$C:$C,$A11,Data_JobCost!$D:$D,F$4) -> 0 | G11: =SUMIFS(Data_JobCost!$L:$L,Data_JobCost!$C:$C,$A11,Data_JobCost!$D:$D,G$4) -> 0 | H11: =SUMIFS(Data_JobCost!$L:$L,Data_JobCost!$C:$C,$A11,Data_JobCost!$D:$D,H$4) -> 0 | I11: =SUMIFS(Data_JobCost!$L:$L,Data_JobCost!$C:$C,$A11,Data_JobCost!$D:$D,I$4) -> 0 | ... M11: =SUMIFS(Data_JobCost!$L:$L,Data_JobCost!$C:$C,$A11,Data_JobCost!$D:$D,M$4) -> 0 | N11: =SUM(B11:M11) -> 438101.97 | O11: =O10+N11 -> 1725447.8
A12: 202501 | B12: =SUMIFS(Data_JobCost!$L:$L,Data_JobCost!$C:$C,$A12,Data_JobCost!$D:$D,B$4) -> 558702.16 | C12: =SUMIFS(Data_JobCost!$L:$L,Data_JobCost!$C:$C,$A12,Data_JobCost!$D:$D,C$4) -> 0 | D12: =SUMIFS(Data_JobCost!$L:$L,Data_JobCost!$C:$C,$A12,Data_JobCost!$D:$D,D$4) -> 0 | E12: =SUMIFS(Data_JobCost!$L:$L,Data_JobCost!$C:$C,$A12,Data_JobCost!$D:$D,E$4) -> 0 | F12: =SUMIFS(Data_JobCost!$L:$L,Data_JobCost!$C:$C,$A12,Data_JobCost!$D:$D,F$4) -> 0 | G12: =SUMIFS(Data_JobCost!$L:$L,Data_JobCost!$C:$C,$A12,Data_JobCost!$D:$D,G$4) -> 0 | H12: =SUMIFS(Data_JobCost!$L:$L,Data_JobCost!$C:$C,$A12,Data_JobCost!$D:$D,H$4) -> 0 | I12: =SUMIFS(Data_JobCost!$L:$L,Data_JobCost!$C:$C,$A12,Data_JobCost!$D:$D,I$4) -> 0 | ... M12: =SUMIFS(Data_JobCost!$L:$L,Data_JobCost!$C:$C,$A12,Data_JobCost!$D:$D,M$4) -> 0 | N12: =SUM(B12:M12) -> 558702.16 | O12: =O11+N12 -> 2284150
A13: 202502 | B13: =SUMIFS(Data_JobCost!$L:$L,Data_JobCost!$C:$C,$A13,Data_JobCost!$D:$D,B$4) -> 520964.18 | C13: =SUMIFS(Data_JobCost!$L:$L,Data_JobCost!$C:$C,$A13,Data_JobCost!$D:$D,C$4) -> 0 | D13: =SUMIFS(Data_JobCost!$L:$L,Data_JobCost!$C:$C,$A13,Data_JobCost!$D:$D,D$4) -> 0 | E13: =SUMIFS(Data_JobCost!$L:$L,Data_JobCost!$C:$C,$A13,Data_JobCost!$D:$D,E$4) -> 0 | F13: =SUMIFS(Data_JobCost!$L:$L,Data_JobCost!$C:$C,$A13,Data_JobCost!$D:$D,F$4) -> 0 | G13: =SUMIFS(Data_JobCost!$L:$L,Data_JobCost!$C:$C,$A13,Data_JobCost!$D:$D,G$4) -> 0 | H13: =SUMIFS(Data_JobCost!$L:$L,Data_JobCost!$C:$C,$A13,Data_JobCost!$D:$D,H$4) -> 0 | I13: =SUMIFS(Data_JobCost!$L:$L,Data_JobCost!$C:$C,$A13,Data_JobCost!$D:$D,I$4) -> 0 | ... M13: =SUMIFS(Data_JobCost!$L:$L,Data_JobCost!$C:$C,$A13,Data_JobCost!$D:$D,M$4) -> 0 | N13: =SUM(B13:M13) -> 520964.18 | O13: =O12+N13 -> 2805114.1
A14: 202503 | B14: =SUMIFS(Data_JobCost!$L:$L,Data_JobCost!$C:$C,$A14,Data_JobCost!$D:$D,B$4) -> 667866.28 | C14: =SUMIFS(Data_JobCost!$L:$L,Data_JobCost!$C:$C,$A14,Data_JobCost!$D:$D,C$4) -> 141082.97 | D14: =SUMIFS(Data_JobCost!$L:$L,Data_JobCost!$C:$C,$A14,Data_JobCost!$D:$D,D$4) -> 0 | E14: =SUMIFS(Data_JobCost!$L:$L,Data_JobCost!$C:$C,$A14,Data_JobCost!$D:$D,E$4) -> 0 | F14: =SUMIFS(Data_JobCost!$L:$L,Data_JobCost!$C:$C,$A14,Data_JobCost!$D:$D,F$4) -> 0 | G14: =SUMIFS(Data_JobCost!$L:$L,Data_JobCost!$C:$C,$A14,Data_JobCost!$D:$D,G$4) -> 0 | H14: =SUMIFS(Data_JobCost!$L:$L,Data_JobCost!$C:$C,$A14,Data_JobCost!$D:$D,H$4) -> 0 | I14: =SUMIFS(Data_JobCost!$L:$L,Data_JobCost!$C:$C,$A14,Data_JobCost!$D:$D,I$4) -> 0 | ... M14: =SUMIFS(Data_JobCost!$L:$L,Data_JobCost!$C:$C,$A14,Data_JobCost!$D:$D,M$4) -> 0 | N14: =SUM(B14:M14) -> 808949.25 | O14: =O13+N14 -> 3614063.4
A15: 202504 | B15: =SUMIFS(Data_JobCost!$L:$L,Data_JobCost!$C:$C,$A15,Data_JobCost!$D:$D,B$4) -> 701693.98 | C15: =SUMIFS(Data_JobCost!$L:$L,Data_JobCost!$C:$C,$A15,Data_JobCost!$D:$D,C$4) -> 375657.23 | D15: =SUMIFS(Data_JobCost!$L:$L,Data_JobCost!$C:$C,$A15,Data_JobCost!$D:$D,D$4) -> 0 | E15: =SUMIFS(Data_JobCost!$L:$L,Data_JobCost!$C:$C,$A15,Data_JobCost!$D:$D,E$4) -> 0 | F15: =SUMIFS(Data_JobCost!$L:$L,Data_JobCost!$C:$C,$A15,Data_JobCost!$D:$D,F$4) -> 0 | G15: =SUMIFS(Data_JobCost!$L:$L,Data_JobCost!$C:$C,$A15,Data_JobCost!$D:$D,G$4) -> 0 | H15: =SUMIFS(Data_JobCost!$L:$L,Data_JobCost!$C:$C,$A15,Data_JobCost!$D:$D,H$4) -> 0 | I15: =SUMIFS(Data_JobCost!$L:$L,Data_JobCost!$C:$C,$A15,Data_JobCost!$D:$D,I$4) -> 0 | ... M15: =SUMIFS(Data_JobCost!$L:$L,Data_JobCost!$C:$C,$A15,Data_JobCost!$D:$D,M$4) -> 0 | N15: =SUM(B15:M15) -> 1077351.2 | O15: =O14+N15 -> 4691414.6
A16: 202505 | B16: =SUMIFS(Data_JobCost!$L:$L,Data_JobCost!$C:$C,$A16,Data_JobCost!$D:$D,B$4) -> 744704.94 | C16: =SUMIFS(Data_JobCost!$L:$L,Data_JobCost!$C:$C,$A16,Data_JobCost!$D:$D,C$4) -> 805086.61 | D16: =SUMIFS(Data_JobCost!$L:$L,Data_JobCost!$C:$C,$A16,Data_JobCost!$D:$D,D$4) -> 66021.25 | E16: =SUMIFS(Data_JobCost!$L:$L,Data_JobCost!$C:$C,$A16,Data_JobCost!$D:$D,E$4) -> 0 | F16: =SUMIFS(Data_JobCost!$L:$L,Data_JobCost!$C:$C,$A16,Data_JobCost!$D:$D,F$4) -> 0 | G16: =SUMIFS(Data_JobCost!$L:$L,Data_JobCost!$C:$C,$A16,Data_JobCost!$D:$D,G$4) -> 0 | H16: =SUMIFS(Data_JobCost!$L:$L,Data_JobCost!$C:$C,$A16,Data_JobCost!$D:$D,H$4) -> 0 | I16: =SUMIFS(Data_JobCost!$L:$L,Data_JobCost!$C:$C,$A16,Data_JobCost!$D:$D,I$4) -> 0 | ... M16: =SUMIFS(Data_JobCost!$L:$L,Data_JobCost!$C:$C,$A16,Data_JobCost!$D:$D,M$4) -> 0 | N16: =SUM(B16:M16) -> 1615812.8 | O16: =O15+N16 -> 6307227.4
A17: 202506 | B17: =SUMIFS(Data_JobCost!$L:$L,Data_JobCost!$C:$C,$A17,Data_JobCost!$D:$D,B$4) -> 726320.95 | C17: =SUMIFS(Data_JobCost!$L:$L,Data_JobCost!$C:$C,$A17,Data_JobCost!$D:$D,C$4) -> 878383.12 | D17: =SUMIFS(Data_JobCost!$L:$L,Data_JobCost!$C:$C,$A17,Data_JobCost!$D:$D,D$4) -> 164577.98 | E17: =SUMIFS(Data_JobCost!$L:$L,Data_JobCost!$C:$C,$A17,Data_JobCost!$D:$D,E$4) -> 99896.84 | F17: =SUMIFS(Data_JobCost!$L:$L,Data_JobCost!$C:$C,$A17,Data_JobCost!$D:$D,F$4) -> 0 | G17: =SUMIFS(Data_JobCost!$L:$L,Data_JobCost!$C:$C,$A17,Data_JobCost!$D:$D,G$4) -> 0 | H17: =SUMIFS(Data_JobCost!$L:$L,Data_JobCost!$C:$C,$A17,Data_JobCost!$D:$D,H$4) -> 0 | I17: =SUMIFS(Data_JobCost!$L:$L,Data_JobCost!$C:$C,$A17,Data_JobCost!$D:$D,I$4) -> 0 | ... M17: =SUMIFS(Data_JobCost!$L:$L,Data_JobCost!$C:$C,$A17,Data_JobCost!$D:$D,M$4) -> 0 | N17: =SUM(B17:M17) -> 1869178.9 | O17: =O16+N17 -> 8176406.3
... A32: 202609 | B32: =SUMIFS(Data_JobCost!$L:$L,Data_JobCost!$C:$C,$A32,Data_JobCost!$D:$D,B$4) -> 0.08 | C32: =SUMIFS(Data_JobCost!$L:$L,Data_JobCost!$C:$C,$A32,Data_JobCost!$D:$D,C$4) -> 468436.37 | D32: =SUMIFS(Data_JobCost!$L:$L,Data_JobCost!$C:$C,$A32,Data_JobCost!$D:$D,D$4) -> 930111.3 | E32: =SUMIFS(Data_JobCost!$L:$L,Data_JobCost!$C:$C,$A32,Data_JobCost!$D:$D,E$4) -> 139144.77 | F32: =SUMIFS(Data_JobCost!$L:$L,Data_JobCost!$C:$C,$A32,Data_JobCost!$D:$D,F$4) -> 1671920.1 | G32: =SUMIFS(Data_JobCost!$L:$L,Data_JobCost!$C:$C,$A32,Data_JobCost!$D:$D,G$4) -> 501877.2 | H32: =SUMIFS(Data_JobCost!$L:$L,Data_JobCost!$C:$C,$A32,Data_JobCost!$D:$D,H$4) -> 949845.75 | I32: =SUMIFS(Data_JobCost!$L:$L,Data_JobCost!$C:$C,$A32,Data_JobCost!$D:$D,I$4) -> 1288492 | ... M32: =SUMIFS(Data_JobCost!$L:$L,Data_JobCost!$C:$C,$A32,Data_JobCost!$D:$D,M$4) -> 299631.7 | N32: =SUM(B32:M32) -> 9147415.3 | O32: =O31+N32 -> 1.1457826e+08
A33: Total | B33: =SUM(B5:B32) -> 14275865 | C33: =SUM(C5:C32) -> 19031041 | D33: =SUM(D5:D32) -> 13766951 | E33: =SUM(E5:E32) -> 8639590.5 | F33: =SUM(F5:F32) -> 15913660 | G33: =SUM(G5:G32) -> 7797690.6 | H33: =SUM(H5:H32) -> 8582224.5 | I33: =SUM(I5:I32) -> 13092124 | ... N33: =SUM(N5:N32) -> 1.1457826e+08

Sheet Cost Report
A1: Cost Report — cost-code level (feeds WIP Schedule and Job Detail)
A2: One row per budget line in the ERP export. Every value is a formula on the Data_ tabs.
A4: Job No | B4: Cost Code | C4: Description | D4: Cost Type | E4: Original Budget | F4: Budget Changes | G4: Revised Budget | H4: Actual Cost | I4: Committed | J4: % Complete | K4: Earned Value | L4: CPI | M4: Forecast Cost (EAC) | N4: Variance at Completion | O4: Cost to Complete | P4: Budget Hours | Q4: Actual Hours | R4: Earned Hours
A5: 23-098 | B5: 01-100 | C5: =INDEX(Data_CostCodes!$B:$B,MATCH($B5,Data_CostCodes!$A:$A,0)) -> General Conditions - Supervision | D5: =INDEX(Data_CostCodes!$D:$D,MATCH($B5,Data_CostCodes!$A:$A,0)) -> Labour | E5: =SUMIFS(Data_Budgets!$C:$C,Data_Budgets!$A:$A,$A5,Data_Budgets!$B:$B,$B5) -> 1055600 | F5: =SUMIFS(Data_Budgets!$D:$D,Data_Budgets!$A:$A,$A5,Data_Budgets!$B:$B,$B5) -> 0 | G5: =E5+F5 -> 1055600 | H5: =SUMIFS(Data_JobCost!$L:$L,Data_JobCost!$D:$D,$A5,Data_JobCost!$E:$E,$B5) -> 1056376.1 | I5: =SUMIFS(Data_Commitments!$E:$E,Data_Commitments!$B:$B,$A5,Data_Commitments!$C:$C,$B5) -> 0 | J5: =SUMIFS(Data_Progress!$C:$C,Data_Progress!$A:$A,$A5,Data_Progress!$B:$B,$B5) -> 0.98 | K5: =G5*J5 -> 1034488 | L5: =IF(H5>0,K5/H5,"") -> 0.97928003 | M5: =IF(I5>0,MAX(I5,H5),IF(J5>0,H5+(G5-K5)/L5,G5)) -> 1077934.8 | N5: =G5-M5 -> -22334.776 | O5: =M5-H5 -> 21558.696 | P5: =SUMIFS(Data_Budgets!$F:$F,Data_Budgets!$A:$A,$A5,Data_Budgets!$B:$B,$B5) -> 11474 | Q5: =SUMIFS(Data_JobCost!$K:$K,Data_JobCost!$D:$D,$A5,Data_JobCost!$E:$E,$B5) -> 11482.4 | R5: =P5*J5 -> 11244.52
A6: 23-098 | B6: 01-200 | C6: =INDEX(Data_CostCodes!$B:$B,MATCH($B6,Data_CostCodes!$A:$A,0)) -> Site Facilities & Temp Services | D6: =INDEX(Data_CostCodes!$D:$D,MATCH($B6,Data_CostCodes!$A:$A,0)) -> Other | E6: =SUMIFS(Data_Budgets!$C:$C,Data_Budgets!$A:$A,$A6,Data_Budgets!$B:$B,$B6) -> 405700 | F6: =SUMIFS(Data_Budgets!$D:$D,Data_Budgets!$A:$A,$A6,Data_Budgets!$B:$B,$B6) -> 0 | G6: =E6+F6 -> 405700 | H6: =SUMIFS(Data_JobCost!$L:$L,Data_JobCost!$D:$D,$A6,Data_JobCost!$E:$E,$B6) -> 411510.56 | I6: =SUMIFS(Data_Commitments!$E:$E,Data_Commitments!$B:$B,$A6,Data_Commitments!$C:$C,$B6) -> 0 | J6: =SUMIFS(Data_Progress!$C:$C,Data_Progress!$A:$A,$A6,Data_Progress!$B:$B,$B6) -> 1 | K6: =G6*J6 -> 405700 | L6: =IF(H6>0,K6/H6,"") -> 0.98587992 | M6: =IF(I6>0,MAX(I6,H6),IF(J6>0,H6+(G6-K6)/L6,G6)) -> 411510.56 | N6: =G6-M6 -> -5810.56 | O6: =M6-H6 -> 0 | P6: =SUMIFS(Data_Budgets!$F:$F,Data_Budgets!$A:$A,$A6,Data_Budgets!$B:$B,$B6) -> 0 | Q6: =SUMIFS(Data_JobCost!$K:$K,Data_JobCost!$D:$D,$A6,Data_JobCost!$E:$E,$B6) -> 0 | R6: =P6*J6 -> 0
A7: 23-098 | B7: 01-500 | C7: =INDEX(Data_CostCodes!$B:$B,MATCH($B7,Data_CostCodes!$A:$A,0)) -> Equipment Rental | D7: =INDEX(Data_CostCodes!$D:$D,MATCH($B7,Data_CostCodes!$A:$A,0)) -> Equipment | E7: =SUMIFS(Data_Budgets!$C:$C,Data_Budgets!$A:$A,$A7,Data_Budgets!$B:$B,$B7) -> 385500 | F7: =SUMIFS(Data_Budgets!$D:$D,Data_Budgets!$A:$A,$A7,Data_Budgets!$B:$B,$B7) -> 0 | G7: =E7+F7 -> 385500 | H7: =SUMIFS(Data_JobCost!$L:$L,Data_JobCost!$D:$D,$A7,Data_JobCost!$E:$E,$B7) -> 398775.35 | I7: =SUMIFS(Data_Commitments!$E:$E,Data_Commitments!$B:$B,$A7,Data_Commitments!$C:$C,$B7) -> 0 | J7: =SUMIFS(Data_Progress!$C:$C,Data_Progress!$A:$A,$A7,Data_Progress!$B:$B,$B7) -> 1 | K7: =G7*J7 -> 385500 | L7: =IF(H7>0,K7/H7,"") -> 0.9667097 | M7: =IF(I7>0,MAX(I7,H7),IF(J7>0,H7+(G7-K7)/L7,G7)) -> 398775.35 | N7: =G7-M7 -> -13275.35 | O7: =M7-H7 -> 0 | P7: =SUMIFS(Data_Budgets!$F:$F,Data_Budgets!$A:$A,$A7,Data_Budgets!$B:$B,$B7) -> 0 | Q7: =SUMIFS(Data_JobCost!$K:$K,Data_JobCost!$D:$D,$A7,Data_JobCost!$E:$E,$B7) -> 0 | R7: =P7*J7 -> 0
A8: 23-098 | B8: 02-200 | C8: =INDEX(Data_CostCodes!$B:$B,MATCH($B8,Data_CostCodes!$A:$A,0)) -> Earthwork & Excavation | D8: =INDEX(Data_CostCodes!$D:$D,MATCH($B8,Data_CostCodes!$A:$A,0)) -> Subcontract | E8: =SUMIFS(Data_Budgets!$C:$C,Data_Budgets!$A:$A,$A8,Data_Budgets!$B:$B,$B8) -> 499000 | F8: =SUMIFS(Data_Budgets!$D:$D,Data_Budgets!$A:$A,$A8,Data_Budgets!$B:$B,$B8) -> 0 | G8: =E8+F8 -> 499000 | H8: =SUMIFS(Data_JobCost!$L:$L,Data_JobCost!$D:$D,$A8,Data_JobCost!$E:$E,$B8) -> 498175.49 | I8: =SUMIFS(Data_Commitments!$E:$E,Data_Commitments!$B:$B,$A8,Data_Commitments!$C:$C,$B8) -> 504300 | J8: =SUMIFS(Data_Progress!$C:$C,Data_Progress!$A:$A,$A8,Data_Progress!$B:$B,$B8) -> 1 | K8: =G8*J8 -> 499000 | L8: =IF(H8>0,K8/H8,"") -> 1.0016551 | M8: =IF(I8>0,MAX(I8,H8),IF(J8>0,H8+(G8-K8)/L8,G8)) -> 504300 | N8: =G8-M8 -> -5300 | O8: =M8-H8 -> 6124.51 | P8: =SUMIFS(Data_Budgets!$F:$F,Data_Budgets!$A:$A,$A8,Data_Budgets!$B:$B,$B8) -> 0 | Q8: =SUMIFS(Data_JobCost!$K:$K,Data_JobCost!$D:$D,$A8,Data_JobCost!$E:$E,$B8) -> 0 | R8: =P8*J8 -> 0
A9: 23-098 | B9: 03-100 | C9: =INDEX(Data_CostCodes!$B:$B,MATCH($B9,Data_CostCodes!$A:$A,0)) -> Concrete Formwork | D9: =INDEX(Data_CostCodes!$D:$D,MATCH($B9,Data_CostCodes!$A:$A,0)) -> Labour | E9: =SUMIFS(Data_Budgets!$C:$C,Data_Budgets!$A:$A,$A9,Data_Budgets!$B:$B,$B9) -> 620700 | F9: =SUMIFS(Data_Budgets!$D:$D,Data_Budgets!$A:$A,$A9,Data_Budgets!$B:$B,$B9) -> 0 | G9: =E9+F9 -> 620700 | H9: =SUMIFS(Data_JobCost!$L:$L,Data_JobCost!$D:$D,$A9,Data_JobCost!$E:$E,$B9) -> 617156.55 | I9: =SUMIFS(Data_Commitments!$E:$E,Data_Commitments!$B:$B,$A9,Data_Commitments!$C:$C,$B9) -> 0 | J9: =SUMIFS(Data_Progress!$C:$C,Data_Progress!$A:$A,$A9,Data_Progress!$B:$B,$B9) -> 1 | K9: =G9*J9 -> 620700 | L9: =IF(H9>0,K9/H9,"") -> 1.0057416 | M9: =IF(I9>0,MAX(I9,H9),IF(J9>0,H9+(G9-K9)/L9,G9)) -> 617156.55 | N9: =G9-M9 -> 3543.45 | O9: =M9-H9 -> 0 | P9: =SUMIFS(Data_Budgets!$F:$F,Data_Budgets!$A:$A,$A9,Data_Budgets!$B:$B,$B9) -> 8388 | Q9: =SUMIFS(Data_JobCost!$K:$K,Data_JobCost!$D:$D,$A9,Data_JobCost!$E:$E,$B9) -> 8339.6 | R9: =P9*J9 -> 8388
